Workbook

Sheet 국문
D5: 번호 : AA01828-0000000012
A7: 제품명 | B7: VARIETY PEAK
A9: 1. 화학제품과 회사에 관한 정보
A10: 가. 제품명 | B10: =B7 -> VARIETY PEAK
A11: 나. 제품의 권고 용도와 사용상의 제한
A12: 제품의 권고 용도 | B12: 화장품 및 생활용품 첨가용
A13: 제품의 사용상의 제한 | B13: 식품 및 식품첨가물로 사용할 수 없음
A14: 다. 제조 및 공급자 정보(수입품의 경우 긴급 연락 가능한 국내 공급자 정보 기재)
A15: 회사명 | B15: 주식회사 아로마준
A16: 주소 | B16: 경기도 수원시 영통구 창룡대로 256번길 91 에이스광교타워2 1301호
A17: 긴급전화번호 | B17: 031-8014-2626
A19: 2. 유해성·위험성
A20: 가.유해성·위험성 분류 | B20: 인화성 액체 : 구분4 피부 부식성/피부 자극성 : 구분2 심한 눈 손상성/눈 자극성 : 구분1 피부 과민성 : 구분1 급성 수생환경 유해성 : 구분1 만성 수생환경 유해성 : 구분1
A21: 나. 예방조치문구를 포함한 경고표지 항목
A22: 그림문자
A24: 신호어 | B24: 위험
A25: 유해·위험문구 | B25: H227 | D25: =VLOOKUP(B25,'[1]위험 안전문구'!$A$2:$C$100,2,0) -> 가연성 액체
D26: =VLOOKUP(B26,'[1]위험 안전문구'!$A$2:$C$100,2,0) -> #N/A
D27: =VLOOKUP(B27,'[1]위험 안전문구'!$A$2:$C$100,2,0) -> #N/A
D28: =VLOOKUP(B28,'[1]위험 안전문구'!$A$2:$C$100,2,0) -> #N/A
D29: =VLOOKUP(B29,'[1]위험 안전문구'!$A$2:$C$100,2,0) -> #N/A
D30: =VLOOKUP(B30,'[1]위험 안전문구'!$A$2:$C$100,2,0) -> #N/A
D31: =VLOOKUP(B31,'[1]위험 안전문구'!$A$2:$C$100,2,0) -> #N/A
D32: =VLOOKUP(B32,'[1]위험 안전문구'!$A$2:$C$100,2,0) -> #N/A
D33: =VLOOKUP(B33,'[1]위험 안전문구'!$A$2:$C$100,2,0) -> #N/A
D34: =VLOOKUP(B34,'[1]위험 안전문구'!$A$2:$C$100,2,0) -> #N/A
D35: =VLOOKUP(B35,'[1]위험 안전문구'!$A$2:$C$100,2,0) -> #N/A
D36: =VLOOKUP(B36,'[1]위험 안전문구'!$A$2:$C$100,2,0) -> #N/A
D37: =VLOOKUP(B37,'[1]위험 안전문구'!$A$2:$C$100,2,0) -> #N/A
... D44: =VLOOKUP(B44,'[1]위험 안전문구'!$A$2:$C$100,2,0) -> #N/A
A45: 예방조치문구
A46: 예방 | D46: =VLOOKUP(B46,'[1]위험 안전문구'!$A$2:$C$100,2,0) -> #N/A
D47: =VLOOKUP(B47,'[1]위험 안전문구'!$A$2:$C$100,2,0) -> #N/A
D48: =VLOOKUP(B48,'[1]위험 안전문구'!$A$2:$C$100,2,0) -> #N/A
D49: =VLOOKUP(B49,'[1]위험 안전문구'!$A$2:$C$100,2,0) -> #N/A
D50: =VLOOKUP(B50,'[1]위험 안전문구'!$A$2:$C$100,2,0) -> #N/A
D51: =VLOOKUP(B51,'[1]위험 안전문구'!$A$2:$C$100,2,0) -> #N/A
D52: =VLOOKUP(B52,'[1]위험 안전문구'!$A$2:$C$100,2,0) -> #N/A
D53: =VLOOKUP(B53,'[1]위험 안전문구'!$A$2:$C$100,2,0) -> #N/A
D54: =VLOOKUP(B54,'[1]위험 안전문구'!$A$2:$C$100,2,0) -> #N/A
...
